Workbook

Sheet Portfolio
A1: Project | B1: Status | C1: Merged / parked into | D1: One-line purpose | E1: Category | F1: Form factor | G1: Primary stack (from spec §3) | H1: Runs on | I1: Best use | J1: DCC group | K1: Best path | L1: Open-source fit | M1: Commercial fit | N1: Rationale | O1: GitHub repo | P1: Your notes | Q1: Open questions (REPORT.md)
A2: am-i-underpaid | B2: Merged → feature | C2: jobs-search-and-apply-tool | E2: Career | F2: — | G2: — | H2: — | I2: Feature of host | J2: Career | K2: — | L2: — | M2: — | N2: Comp-check tab that feeds the compensation floor. | O2: https://github.com/snknitin/am-i-underpaid | Q2: —
A3: jobs-search-and-apply-tool | B3: Greenfield · host | C3: absorbs am-i-underpaid | D3: A private, Windows-localhost career operations console for one job seeker: capture roles from user-selected sources (paste + official Greenhouse/Lever/Ashby feeds), rank fit against a versioned target universe with visible hard-gate/score explanations, build truthful application packets where every claim resolves to an approved evidence record, and track applications/follow-ups — with final submission permanently human. It is the upstream producer of the portable career handoffs (`interview-prep.json`, `study-gaps.json`, `calendar-actions.ics`) defined in §4. It absorbs Am I Underpaid as the **Comp check** feature: an honest compensation range (cohort size and dataset year always shown) and sustainable-rate floor that can be proposed as the target universe's compensation floor. | E3: Career | F3: Web dashboard | G3: FastAPI, HTMX, Jinja, DuckDB, Playwright, SQLite, React | H3: Windows desktop | I3: DCC tab | J3: Career | K3: Personal → Commercial | L3: Medium | M3: Medium | N3: Truthful, evidence-gated packets differentiate from auto-apply tools; job seekers pay. | O3: https://github.com/snknitin/jobs-search-and-apply-tool | Q3: 3 blocking · 1 questions · 1 proposals
A4: mock-interview-gauntlet | B4: Greenfield | D4: A private, loopback-only interview simulator for senior technical IC roles (MTS/AI Engineer, Staff/Principal DS, FDE, Research Scientist): an approved job posting plus approved candidate evidence drives bounded practice sessions, evidence-linked AI critique with anchored bands, selective independent verification, and same-scenario retries. It critiques observable reasoning against a versioned rubric. | E4: Career | F4: Web dashboard | G4: FastAPI, Jinja, Playwright, SQLite | H4: Windows desktop (+Spark inference) | I4: DCC tab | J4: Career | K4: Personal → Commercial | L4: Medium | M4: High | N4: Interview prep is a proven paid market; evidence-linked critique without hiring verdicts is a strong angle. | O4: https://github.com/snknitin/mock-interview-gauntlet | Q4: 1 blocking · 1 questions · 2 proposals
A5: resume-blueprint-studio | B5: Greenfield | D5: A local-first Windows web app that turns a resume (PDF/DOCX) into an explorable, source-linked preparation library: faithful page viewer, exploded section/bullet cards in page-side lanes, and connected action cards (Explain, Rephrase, Primer, FAQ, Research, System design, Recall) whose outputs publish as Markdown into the owner's Obsidian Personal Sync vault. Single user; Windows owns all state; Spark supplies inference through an existing route. All 17 confirmed product decisions live in `docs/decisions.json` and are binding. | E5: Career | F5: Web dashboard (React/Vite) | G5: FastAPI, SQLite, React | H5: Windows desktop | I5: DCC tab | J5: Career | K5: Personal | L5: Medium | M5: Medium | N5: Explorable resume prep library; publishes into the vault. | O5: https://github.com/snknitin/resume-blueprint-studio | Q5: 1 blocking · 0 questions · 2 proposals
A6: recruiting-agency | B6: Greenfield | D6: A local hiring-design desk: turn a vague hiring request into an outcome-focused JD, precommitted versioned rubric, channel plan, blind evidence-linked candidate summaries, outreach drafts, and a structured interview kit — with humans recording every decision and override. Decision support, never automated rejection. | E6: Career (employer side) | F6: Web dashboard | G6: SvelteKit, FastAPI, SQLite | H6: Windows desktop | I6: DCC tab | J6: Client services | K6: Commercial | L6: Low | M6: Medium | N6: Hiring-design desk for small teams; decision support, never automated rejection. | O6: https://github.com/snknitin/recruiting-agency | Q6: 0 blocking · 3 questions · 0 proposals
A7: ai-event-matchmaker | B7: Merged → feature | C7: event-ops-agency | E7: Client services | F7: — | G7: — | H7: — | I7: Feature of host | J7: Client services | K7: — | L7: — | M7: — | N7: Attendee matchmaking tab. | O7: https://github.com/snknitin/ai-event-matchmaker | Q7: —
A8: community-ops-agency | B8: Greenfield | D8: A human-supervised operations desk for one community: import rules, members, events, and messages (manual JSON/CSV export), classify activity with evidence, and produce the weekly operating kit — digest, moderation suggestion queue, onboarding page, ICS calendar, unanswered-question tracker, and three low-pressure engagement prompts. Every external action is a human-approved draft that the owner copies out by hand. | E8: Client services | F8: Web dashboard | G8: FastAPI, HTMX, Jinja, SQLite | H8: Windows desktop | I8: DCC tab | J8: Client services | K8: Commercial | L8: Medium | M8: Medium | N8: Weekly community operating kit. | O8: https://github.com/snknitin/community-ops-agency | Q8: 0 blocking · 2 questions · 0 proposals
A9: customer-support-agency | B9: Greenfield · host | C9: absorbs support-faq-builder, google-review-reply-desk | D9: Local-first analysis app: import a de-identified ticket export plus policy docs, cluster recurring issues, and draft policy-grounded macros, FAQs, an escalation tree, and a quality rubric — all human-reviewed and exported as an operations pack. It helps an operator design support, never run it. It also hosts two merged feature tabs: **FAQ program** (gap-ranked FAQ coverage, evidence-gap queue, help-center Markdown export, from `support-faq-builder`) and **Review replies** (manual-post public review replies grounded in the same approved policy evidence, from `google-review-reply-desk`). | E9: Client services | F9: Web dashboard | G9: Streamlit, FastAPI, sentence-transformers, Polars, Playwright, SQLite, React | H9: Windows desktop | I9: DCC tab | J9: Client services | K9: Commercial | L9: Medium | M9: High | N9: Support-design ops pack for small businesses. | O9: https://github.com/snknitin/customer-support-agency | Q9: 0 blocking · 3 questions · 0 proposals
A10: event-ops-agency | B10: Greenfield · host | C10: absorbs ai-event-matchmaker | D10: A local Next.js app that turns an event brief plus working spreadsheets (CSV) into a deadline-aware operations pack: tasks, schedule-conflict checks, run-of-show, host script, speaker cards, sponsor matrix, and reviewable message drafts. Serves one organizer running one event at a time. It also hosts the merged **Matchmaking** feature (from `ai-event-matchmaker`): a consent-controlled, auto-expiring "meet these people" queue for the same event's attendees, scored deterministically with published weights. | E10: Client services | F10: Web dashboard (Next.js) | G10: SvelteKit, Next.js, sentence-transformers, Playwright, SQLite, React | H10: Windows desktop | I10: DCC tab | J10: Client services | K10: Commercial | L10: Medium | M10: Medium | N10: Event ops + matchmaking for organizers. | O10: https://github.com/snknitin/event-ops-agency | Q10: 1 blocking · 1 questions · 0 proposals
A11: google-review-reply-desk | B11: Merged → feature | C11: customer-support-agency | E11: Client services | F11: — | G11: — | H11: — | I11: Feature of host | J11: Client services | K11: — | L11: — | M11: — | N11: Public review replies tab. | O11: https://github.com/snknitin/google-review-reply-desk | Q11: —
A12: knowledge-base-agency | B12: Greenfield | D12: A local pipeline + web app that turns a client's supplied documents into a citation-first knowledge base: parsed sources with QA, hybrid search, cited answers that abstain without evidence, a golden-question evaluation harness, and a repeatable delivery package with refresh instructions. Serves a solo operator delivering KBs to clients. | E12: Client services | F12: Web dashboard | G12: FastAPI, HTMX, Jinja, sentence-transformers, SQLite | H12: Windows desktop | I12: DCC tab | J12: Client services | K12: Commercial | L12: Medium | M12: High | N12: Kept separate by your choice; citation-first KB delivery for clients. | O12: https://github.com/snknitin/knowledge-base-agency | Q12: 0 blocking · 2 questions · 0 proposals
A13: meta-ad-creative-studio | B13: Greenfield · host | C13: absorbs paid-ad-account-audit | D13: A local creative workbench that turns one product's evidence, audience, offer, and brand system into intentionally different Meta ad concepts, renders placement-ready creative packs, and joins imported results back to the hypothesis that produced each asset. It makes disciplined creative testing cheap — it does not predict winners. It also hosts the merged **Audit** tab (from `paid-ad-account-audit`): ten deterministic audit rules over imported Google/Meta CSV exports whose accepted findings feed the studio's hypotheses and whose imported rows feed the results join. | E13: Client services | F13: Web dashboard (SvelteKit) | G13: SvelteKit, Next.js, FastAPI, Polars, DuckDB, Playwright, FFmpeg, SQLite, React | H13: Windows desktop | I13: DCC tab | J13: Client services | K13: Commercial | L13: Low | M13: High | N13: Ads audit + creative testing studio for small advertisers. | O13: https://github.com/snknitin/meta-ad-creative-studio | Q13: 0 blocking · 3 questions · 0 proposals
A14: paid-ad-account-audit | B14: Merged → feature | C14: meta-ad-creative-studio | E14: Client services | F14: — | G14: — | H14: — | I14: Feature of host | J14: Client services | K14: — | L14: — | M14: — | N14: Audit tab. | O14: https://github.com/snknitin/paid-ad-account-audit | Q14: —
A15: support-faq-builder | B15: Merged → feature | C15: customer-support-agency | E15: Client services | F15: — | G15: — | H15: — | I15: Feature of host | J15: Client services | K15: — | L15: — | M15: — | N15: Deduplicated into the support pipeline. | O15: https://github.com/snknitin/support-faq-builder | Q15: —
A16: agents-board | B16: Brownfield (live) | D16: One place to plan, start and check overnight agent work across Claude Code, Codex and Hermes. | E16: Dev | F16: Web dashboard | G16: — | H16: Windows desktop | I16: DCC tab | J16: Dev | K16: Personal | L16: Medium | M16: Low | N16: Your overnight agent board (DCC Nightly tab). | O16: https://github.com/snknitin/agents-board | Q16: —
A17: dies-at-user-50 | B17: Greenfield | D17: An authorized synthetic-user gauntlet: ramp k6 HTTP load plus a Playwright browser journey against localhost (or an ownership-verified host) until explicit latency/error thresholds break, then report the first failing stage with evidence, a bottleneck diagnosis, and a playful death certificate. The artifact is the diagnosis, not a leaderboard. | E17: Dev | F17: CLI (k6 + Playwright) | G17: Next.js, Playwright, k6 | H17: Windows / Spark | I17: CLI | J17: Dev | K17: Open-source | L17: High | M17: Medium | N17: Playful load-test 'death certificate' is a shareable dev tool. | O17: https://github.com/snknitin/dies-at-user-50 | Q17: 0 blocking · 1 questions · 0 proposals
A18: maintainer-desk | B18: Greenfield · host | C18: absorbs pr-factory | D18: A supervised operations desk for one GitHub repository: it ingests issues/PRs read-only, builds triage proposal cards (duplicates, missing info, labels, draft replies), reproduces bugs in disposable containers, and drafts PR reviews/patches — with every GitHub mutation gated behind an explicit maintainer approval record. V0 runs entirely against a local fixture repo and stops before any GitHub write. It absorbs PR Factory as the **Tournament** feature: when the maintainer asks the desk for a code patch, two isolated candidate agents race in Docker-backed worktrees against human-approved acceptance tests, deterministic QA scores them, and a deterministic judge picks one patch with its full decision trail — stopping before push or merge. | E18: Dev | F18: Web dashboard | G18: SvelteKit, FastAPI, SQLite, Docker | H18: Windows desktop / Spark | I18: DCC tab | J18: Dev | K18: Open-source | L18: High | M18: Medium | N18: Supervised OSS-maintainer desk; resonates with open-source maintainers. | O18: https://github.com/snknitin/maintainer-desk | Q18: 1 blocking · 2 questions · 0 proposals
A19: on-call-autopilot | B19: Greenfield | D19: A supervised incident investigator that replays a frozen telemetry bundle from a synthetic broken deploy, builds an evidence-backed timeline, ranks hypotheses with cited event IDs, patches a fixture in an isolated worktree, verifies locally, and emits a mock PR + postmortem for human approval. Serves an on-call engineer practicing against replay fixtures. | E19: Dev | F19: CLI + web | G19: SvelteKit, FastAPI, DuckDB, SQLite, Docker | H19: Windows / Spark | I19: DCC tab | J19: Dev | K19: Open-source | L19: High | M19: Medium | N19: Incident-practice trainer. | O19: https://github.com/snknitin/on-call-autopilot | Q19: 0 blocking · 1 questions · 0 proposals
A20: pr-factory | B20: Merged → feature | C20: maintainer-desk | E20: Dev | F20: — | G20: — | H20: — | I20: Feature of host | J20: Dev | K20: — | L20: — | M20: — | N20: Patch-tournament engine. | O20: https://github.com/snknitin/pr-factory | Q20: —
A21: adaptive-vision-glasses | B21: Greenfield | D21: A phone-based electronic magnifier for specific near/far tasks (reading labels, whiteboards, menus): zoom with autofocus lock, freeze frame, contrast profiles, OCR with reflowed large text, and text-to-speech — prioritizing low latency, readable contrast, and privacy. It is an assistive magnifier, not glasses hardware. | E21: Devices | F21: Android app | G21: Kotlin/Compose, PyTorch | H21: Phone | I21: Phone app | J21: — | K21: Open-source (assistive) | L21: High | M21: Low | N21: Assistive magnifier; open source helps people who need it. | O21: https://github.com/snknitin/adaptive-vision-glasses | Q21: 1 blocking · 2 questions · 0 proposals
A22: any-app-widget-maker | B22: Greenfield | D22: A user-configured widget builder: pick a permitted data source, map a small piece of it through simple formatting rules, and get a glanceable home-screen widget with deep-link buttons — honest about what closed apps expose ("any app" is a direction, not a guarantee). MVP is Android-first with three source types, four layouts, read-only data. | E22: Devices | F22: Android app | G22: Kotlin/Compose | H22: Phone | I22: Phone app | J22: — | K22: Commercial | L22: Medium | M22: Medium | N22: Widget builders sell on the Play Store. | O22: https://github.com/snknitin/any-app-widget-maker | Q22: 0 blocking · 2 questions · 0 proposals
A23: ar-scale-lens | B23: Greenfield | D23: An Android ARCore camera tool that makes an abstract measurement feel physical: type "91 cm" or "2,000 sq ft" and walk around a correctly scaled line, rectangle, or known-size reference object placed on the floor, then export an annotated photo. Every result carries device capability, tracking quality, and an error band — approximate by design. | E23: Devices | F23: Android app (ARCore) | G23: Kotlin/Compose, ARCore | H23: Phone | I23: Phone app | J23: — | K23: Open-source | L23: Medium | M23: Medium | N23: Scale-visualization niche. | O23: https://github.com/snknitin/ar-scale-lens | Q23: 1 blocking · 1 questions · 0 proposals
A24: drone-mission-mapper | B24: Greenfield | D24: Simulation-first mission planner: draw a survey area on a map, generate a safe flight pattern with battery/coverage estimates, validate it, fly it in SITL only, then georeference captured frames and run text-prompted object detection whose hits require human confirmation. No physical takeoff anywhere in this build. | E24: Devices | F24: Web + SITL | G24: Tauri, FastAPI, SQLite, React | H24: Windows (WSL2) / Linux | I24: Standalone web | J24: Labs | K24: Open-source | L24: High | M24: Medium | N24: Simulation-first mission planning. | O24: https://github.com/snknitin/drone-mission-mapper | Q24: 0 blocking · 2 questions · 0 proposals
A25: field-pokedex | B25: Greenfield | D25: An Expo mobile app that identifies likely plant species from a photo via a hosted identification API, shows ranked candidates with confidence and lookalikes, pulls attributed taxonomy/facts, and saves confirmed-or-unresolved observations into a private collectible journal. Serves one naturalist in one region. | E25: Devices | F25: Phone app (Expo) | G25: Expo, SQLite, React | H25: Phone | I25: Phone app | J25: — | K25: Personal → Commercial | L25: Medium | M25: Medium | N25: Collectible plant journal. | O25: https://github.com/snknitin/field-pokedex | Q25: 0 blocking · 2 questions · 0 proposals
A26: 27-clicks-to-cancel | B26: Merged → feature | C26: paisa-vasool-subscriptions | E26: Finance | F26: — | G26: — | H26: — | I26: Feature of host | J26: Money | K26: — | L26: — | M26: — | N26: Cancel-assist step inside Paisa. | O26: https://github.com/snknitin/27-clicks-to-cancel | Q26: —
A27: edge-desk | B27: Merged → feature | C27: event-market-research-terminal | E27: Finance | F27: — | G27: — | H27: — | I27: Feature of host | J27: Money | K27: — | L27: — | M27: — | N27: Its alerts and ambiguity warnings now live in EMRT. | O27: https://github.com/snknitin/edge-desk | Q27: —
A28: event-market-research-terminal | B28: Greenfield · host | C28: absorbs edge-desk | D28: A research-only terminal for event markets and crypto narratives: for each manually-watched market it freezes timestamped evidence dossiers (resolution rules, price/liquidity/spread, catalysts, primary sources, counterarguments, narrative shifts, falsifiers), logs paper decisions before outcomes, and scores calibration later. Anti-hype by design: base rate, liquidity, time-to-resolution, and the strongest disconfirming evidence always render before sentiment. Merged feature: **Edge Desk** adds liquidity-gated market-move alerts, resolution-rule versioning with ambiguity warnings, paper positions, and baseline replay as a "Moves & rules" tab. | E28: Finance | F28: Web dashboard (Streamlit) | G28: Streamlit, FastAPI, n8n, Polars, DuckDB, SQLite | H28: Windows desktop | I28: DCC tab | J28: Money | K28: Personal → Open-source | L28: Medium | M28: Medium | N28: Research-only calibration workspace; a commercial route exists but compliance/overconfidence costs are high. | O28: https://github.com/snknitin/event-market-research-terminal | Q28: 1 blocking · 2 questions · 1 proposals
A29: finance-ops-agency | B29: Greenfield · host | C29: absorbs invoice-chaser-agent, tax-packet-autopilot | D29: A local finance-operations desk for a freelancer: imports invoice/expense/bank/reimbursement exports, proposes payment↔invoice matches, routes uncertainty to a review queue, and produces receivable aging, a payable calendar, three-scenario cash view, and a review-ready monthly close memo with an evidence manifest. Merged features: **Invoice Chaser** adds a Receivables → Chase tab that drafts tone-escalating reminders from the same imports (every reminder still needs a click; nothing is sent by the app), and **Tax Packet** adds a "Tax packet for CA" tab that turns imported invoices/receipts into a reviewed, deduplicated GST evidence packet. | E29: Finance | F29: Web dashboard | G29: Streamlit, FastAPI, Jinja, Polars, DuckDB, SQLite | H29: Windows desktop | I29: DCC tab | J29: Money | K29: Commercial | L29: Medium | M29: High | N29: Freelancer AR + monthly close + CA tax packet is a sellable bundle, especially for Indian freelancers and their CAs. | O29: https://github.com/snknitin/finance-ops-agency | Q29: 1 blocking · 2 questions · 1 proposals
A30: finance-signals-dashboard | B30: Greenfield · host | C30: absorbs market-mood-cards | D30: A read-only, local-first personal dashboard that ranks a ten-instrument India/US watchlist by "research priority" (which instrument deserves the next unit of investigation), with every rank fully reproducible from stored formulas, raw-data hashes, and human-approved signal policies. Serves exactly one user on one Windows machine and appears in Dashboard Command Center's Finance group, which `personal-finance-cockpit` composes. Merged feature: **Morning mood** (formerly the standalone `market-mood-cards`) adds a Morning tab. At 08:15 IST it publishes one calm, immutable issue: exact completed-session moves for six named indices, one BTC/USD display observation, deduplicated headlines and a template summary. It is built on this app's instruments, ingestion, raw store, lease/receipts, scheduler and SQLite. | E30: Finance | F30: Web dashboard (SvelteKit) | G30: SvelteKit, FastAPI, Jinja, Playwright, SQLite | H30: Windows desktop | I30: DCC tab | J30: Money | K30: Personal | L30: Medium | M30: Low | N30: Market-data licences block redistribution; could open-source as a bring-your-own-data engine. | O30: https://github.com/snknitin/finance-signals-dashboard | Q30: 1 blocking · 9 questions · 2 proposals
A31: invoice-chaser-agent | B31: Merged → feature | C31: finance-ops-agency | E31: Finance | F31: — | G31: — | H31: — | I31: Feature of host | J31: Money | K31: — | L31: — | M31: — | N31: Receivables/chase tab inside Finance Ops. | O31: https://github.com/snknitin/invoice-chaser-agent | Q31: —
A32: latte-into-lambo | B32: Merged → feature | C32: net-worth-command-center | E32: Finance | F32: — | G32: — | H32: — | I32: Feature of host | J32: Money | K32: — | L32: — | M32: — | N32: Now Net Worth's What-if tab. | O32: https://github.com/snknitin/latte-into-lambo | Q32: —
A33: market-mood-cards | B33: Merged → feature | C33: finance-signals-dashboard | D33: A standalone, Spark-hosted morning-briefing pipeline and private dashboard: at a configured cutoff it publishes one immutable "issue" with exact completed-session moves for six named equity indices (NIFTY 50, S&P 500, Nikkei 225, KOSPI, STI, CSI 300) plus BTC/USD spot, deduplicated regional headlines, a deterministic template summary, and full evidence provenance. Serves one user via tailnet through Dashboard Command Center. | E33: Finance | F33: — | G33: FastAPI, Jinja, SQLite | H33: — | I33: Feature of host | J33: Money | K33: — | L33: — | M33: — | N33: Morning tab of Finance Signals. | O33: https://github.com/snknitin/market-mood-cards | Q33: —
A34: net-worth-command-center | B34: Greenfield · host | C34: absorbs latte-into-lambo | D34: A private, local-first personal-finance record for one person: import statements/balances, reconcile them against evidence, and produce locked month-end USD snapshots with known/estimated/excluded totals — all deterministic, with no model authority over money. Serves the single owner on one Windows machine, registered as a Money module in Dashboard Command Center by URL/health only. Merged feature: **What-if** (formerly the standalone `latte-into-lambo`) adds a counterfactual tab that replays the user's reviewed spend against frozen price/FX/CPI data releases through a pure, fingerprinted calculation kernel, reading Net Worth's own committed transactions in-process. | E34: Finance | F34: Web dashboard | G34: FastAPI, Jinja, SQLite | H34: Windows desktop | I34: DCC tab | J34: Money | K34: Personal | L34: Low | M34: Low | N34: Private balance-sheet record. Its value is trust in your own numbers, not distribution. | O34: https://github.com/snknitin/net-worth-command-center | Q34: 2 blocking · 5 questions · 2 proposals
A35: paisa-vasool-subscriptions | B35: Greenfield · host | C35: absorbs renewal-guard, 27-clicks-to-cancel | D35: A private, local-first subscription-utilization tracker for one user: it discovers recurring charges from years of transaction history (via a read-only Net Worth view or manual registry), explains which optional subscriptions are underused, prepares reviewed cancellation/downgrade/use-better actions, and counts savings only after a later statement proves the charge stopped. Merged features: **Renewal Guard** makes receipts/invoices/warranties Paisa's second evidence source with a Renewals & warranties tab, and **Cancel Assist** (from 27-clicks-to-cancel) executes an approved cancellation packet in a supervised browser with a page-state-bound human-approval hard stop before the final click. | E35: Finance | F35: Web dashboard | G35: SvelteKit, FastAPI, Jinja, Playwright, SQLite | H35: Windows desktop | I35: DCC tab | J35: Money | K35: Personal → Commercial | L35: Medium | M35: Medium | N35: Verified cancellations + utilization is a real consumer pain; local-first privacy is the differentiator. | O35: https://github.com/snknitin/paisa-vasool-subscriptions | Q35: 1 blocking · 4 questions · 3 proposals
A36: personal-finance-cockpit | B36: Greenfield | D36: The **Finance group inside Dashboard Command Center (DCC)** — not a standalone app (owner decision 2026-10-20). DCC already owns navigation, windows, sessions, endpoint health probes and display; each finance module owns its own data, rules, actions and UI. This project owns only what neither does: 1. **Composition** — which finance modules register in DCC's Finance group, in what order, with which endpoints, health URLs, session boundaries and activation state: Balance Sheet (`net-worth-command-center`), Subscriptions (`paisa-vasool-subscriptions`), Market Signals (`finance-signals-dashboard`), Crypto & Event Markets (`event-market-research-terminal`). It emits DCC registry records; the owner imports them through DCC's existing **Import registry**. 2. **A thin loopback aggregator** registered as the group's first dashboard, *Finance Overview*: the cross-module provenance/health board (source time, version, freshness, backup state per module), the digest preview and the export index — on one read-only page, plus a DCC capability manifest carrying a one-line group status. 3. **One finance notification policy** (triggers, previews, quiet hours, one digest). | E36: Finance | F36: DCC Finance group + overview page | G36: FastAPI, Jinja, SQLite | H36: Windows desktop | I36: DCC group | J36: Money | K36: Personal | L36: Low | M36: Low | N36: Composition layer only: groups the finance apps inside Dashboard Command Center. | O36: https://github.com/snknitin/personal-finance-cockpit | Q36: 1 blocking · 1 questions · 3 proposals
A37: renewal-guard | B37: Merged → feature | C37: paisa-vasool-subscriptions | E37: Finance | F37: — | G37: — | H37: — | I37: Feature of host | J37: Money | K37: — | L37: — | M37: — | N37: Receipts/warranties tab inside Paisa. | O37: https://github.com/snknitin/renewal-guard | Q37: —
A38: tax-packet-autopilot | B38: Merged → feature | C38: finance-ops-agency | E38: Finance | F38: — | G38: — | H38: — | I38: Feature of host | J38: Money | K38: — | L38: — | M38: — | N38: Tax-packet-for-CA tab inside Finance Ops. | O38: https://github.com/snknitin/tax-packet-autopilot | Q38: —
A39: live-chess-tutor | B39: Greenfield | D39: A local desktop chess board for guided practice: during unrated games against embedded Stockfish (or positions from personal PGNs), it spots teachable moments before the move is committed, asks the learner to reason ("checks, captures, threats?"), reveals hints progressively, and logs concept mastery for spaced review. Pedagogy and timing are the product; the engine analysis is commodity. | E39: Games | F39: Desktop app | G39: Tauri, SQLite | H39: Windows desktop | I39: Standalone desktop | J39: — | K39: Open-source | L39: High | M39: Medium | N39: Pedagogy-first chess tutor. | O39: https://github.com/snknitin/live-chess-tutor | Q39: 0 blocking · 0 questions · 0 proposals
A40: murder-mystery-game-master | B40: Greenfield | D40: A deterministic party-game engine for 45–90 minute murder mysteries on a local LAN: it privately assigns fictional roles, releases timed clues, collects theories and one vote, and narrates a reveal — with AI adding bounded flavor while an append-only event log keeps state consistent and replayable. Works for a six-player party and as a single-player mental exercise (the engine reveals the solution if nobody pieces it together). | E40: Games | F40: LAN party web app | G40: Next.js, SQLite | H40: Windows desktop + LAN | I40: Party / LAN app | J40: — | K40: Commercial | L40: Medium | M40: Medium | N40: Party-game kits sell; AI-bounded narration is a hook. | O40: https://github.com/snknitin/murder-mystery-game-master | Q40: 0 blocking · 2 questions · 2 proposals
...

Sheet Merges
A1: Project | B1: Status | C1: Now lives in | D1: Note
A2: am-i-underpaid | B2: Merged → feature | C2: jobs-search-and-apply-tool | D2: Comp-check tab that feeds the compensation floor.
A3: ai-event-matchmaker | B3: Merged → feature | C3: event-ops-agency | D3: Attendee matchmaking tab.
A4: google-review-reply-desk | B4: Merged → feature | C4: customer-support-agency | D4: Public review replies tab.
A5: paid-ad-account-audit | B5: Merged → feature | C5: meta-ad-creative-studio | D5: Audit tab.
A6: support-faq-builder | B6: Merged → feature | C6: customer-support-agency | D6: Deduplicated into the support pipeline.
A7: pr-factory | B7: Merged → feature | C7: maintainer-desk | D7: Patch-tournament engine.
A8: 27-clicks-to-cancel | B8: Merged → feature | C8: paisa-vasool-subscriptions | D8: Cancel-assist step inside Paisa.
A9: edge-desk | B9: Merged → feature | C9: event-market-research-terminal | D9: Its alerts and ambiguity warnings now live in EMRT.
A10: invoice-chaser-agent | B10: Merged → feature | C10: finance-ops-agency | D10: Receivables/chase tab inside Finance Ops.
A11: latte-into-lambo | B11: Merged → feature | C11: net-worth-command-center | D11: Now Net Worth's What-if tab.
A12: market-mood-cards | B12: Merged → feature | C12: finance-signals-dashboard | D12: Morning tab of Finance Signals.
... A48: startup-graveyard | B48: Merged → feature | C48: side-hustle-radar | D48: Failure-research tab.

Sheet DCC Groups
A1: DCC group | B1: Dashboards in group (live count) | C1: Members
A2: Money | B2: =COUNTIFS(Portfolio!$J$2:$J$139,A2,Portfolio!$I$2:$I$139,"DCC*")+COUNTIFS(Portfolio!$J$2:$J$139,A2,Portfolio!$I$2:$I$139,"Standalone / DCC tab") | C2: event-market-research-terminal, finance-ops-agency, finance-signals-dashboard, net-worth-command-center, paisa-vasool-subscriptions, personal-finance-cockpit
A3: Career | B3: =COUNTIFS(Portfolio!$J$2:$J$139,A3,Portfolio!$I$2:$I$139,"DCC*")+COUNTIFS(Portfolio!$J$2:$J$139,A3,Portfolio!$I$2:$I$139,"Standalone / DCC tab") | C3: jobs-search-and-apply-tool, mock-interview-gauntlet, resume-blueprint-studio
A4: Learning | B4: =COUNTIFS(Portfolio!$J$2:$J$139,A4,Portfolio!$I$2:$I$139,"DCC*")+COUNTIFS(Portfolio!$J$2:$J$139,A4,Portfolio!$I$2:$I$139,"Standalone / DCC tab") | C4: kaggle-learning-center, personal-study-curriculum, quiz-master, tiktok-learning-center, youtube-learning-center
A5: Signals | B5: =COUNTIFS(Portfolio!$J$2:$J$139,A5,Portfolio!$I$2:$I$139,"DCC*")+COUNTIFS(Portfolio!$J$2:$J$139,A5,Portfolio!$I$2:$I$139,"Standalone / DCC tab") | C5: fresh-brief, social-capture
A6: Publishing | B6: =COUNTIFS(Portfolio!$J$2:$J$139,A6,Portfolio!$I$2:$I$139,"DCC*")+COUNTIFS(Portfolio!$J$2:$J$139,A6,Portfolio!$I$2:$I$139,"Standalone / DCC tab") | C6: creator-content-engine, landing-page-conversion-agency, seo-agency-crew, shopify-product-page-optimizer
A7: Ventures | B7: =COUNTIFS(Portfolio!$J$2:$J$139,A7,Portfolio!$I$2:$I$139,"DCC*")+COUNTIFS(Portfolio!$J$2:$J$139,A7,Portfolio!$I$2:$I$139,"Standalone / DCC tab") | C7: ai-implementation-agency, competitive-intelligence-agency, deal-desk-agency, demand-generation-workbench, sales-development-agency, side-hustle-radar, user-research-agency
A8: Client services | B8: =COUNTIFS(Portfolio!$J$2:$J$139,A8,Portfolio!$I$2:$I$139,"DCC*")+COUNTIFS(Portfolio!$J$2:$J$139,A8,Portfolio!$I$2:$I$139,"Standalone / DCC tab") | C8: community-ops-agency, customer-support-agency, event-ops-agency, knowledge-base-agency, meta-ad-creative-studio, recruiting-agency
A9: Personal | B9: =COUNTIFS(Portfolio!$J$2:$J$139,A9,Portfolio!$I$2:$I$139,"DCC*")+COUNTIFS(Portfolio!$J$2:$J$139,A9,Portfolio!$I$2:$I$139,"Standalone / DCC tab") | C9: daily-parent-check-in, dunbar-dossier, inbox-zero-mercenary, motto-agent-council
A10: Dev | B10: =COUNTIFS(Portfolio!$J$2:$J$139,A10,Portfolio!$I$2:$I$139,"DCC*")+COUNTIFS(Portfolio!$J$2:$J$139,A10,Portfolio!$I$2:$I$139,"Standalone / DCC tab") | C10: agents-board, maintainer-desk, on-call-autopilot
A11: Studio | B11: =COUNTIFS(Portfolio!$J$2:$J$139,A11,Portfolio!$I$2:$I$139,"DCC*")+COUNTIFS(Portfolio!$J$2:$J$139,A11,Portfolio!$I$2:$I$139,"Standalone / DCC tab")
A12: Labs | B12: =COUNTIFS(Portfolio!$J$2:$J$139,A12,Portfolio!$I$2:$I$139,"DCC*")+COUNTIFS(Portfolio!$J$2:$J$139,A12,Portfolio!$I$2:$I$139,"Standalone / DCC tab")

Sheet Summary
A1: Projects in portfolio | B1: =COUNTA(Portfolio!A2:A139)
A3: By status
A4: Brownfield (live) | B4: =COUNTIF(Portfolio!$B$2:$B$139,A4)
A5: Built elsewhere | B5: =COUNTIF(Portfolio!$B$2:$B$139,A5)
A6: Greenfield | B6: =COUNTIF(Portfolio!$B$2:$B$139,A6)
A7: Greenfield · host | B7: =COUNTIF(Portfolio!$B$2:$B$139,A7)
A8: Kept (ideas ported) | B8: =COUNTIF(Portfolio!$B$2:$B$139,A8)
A9: Merged → feature | B9: =COUNTIF(Portfolio!$B$2:$B$139,A9)
A10: Parked (archived) | B10: =COUNTIF(Portfolio!$B$2:$B$139,A10)
A11: Retired (archived) | B11: =COUNTIF(Portfolio!$B$2:$B$139,A11)
A12: Third-party | B12: =COUNTIF(Portfolio!$B$2:$B$139,A12)
A13: Total | B13: =SUM(B4:B12)
A15: By best use
A16: Archived | B16: =COUNTIF(Portfolio!$I$2:$I$139,A16)
A17: Browser extension | B17: =COUNTIF(Portfolio!$I$2:$I$139,A17)
A18: CLI | B18: =COUNTIF(Portfolio!$I$2:$I$139,A18)
A19: CLI + Obsidian | B19: =COUNTIF(Portfolio!$I$2:$I$139,A19)
A20: CLI + hosted previews | B20: =COUNTIF(Portfolio!$I$2:$I$139,A20)
A21: DCC group | B21: =COUNTIF(Portfolio!$I$2:$I$139,A21)
A22: DCC tab | B22: =COUNTIF(Portfolio!$I$2:$I$139,A22)
A23: Excluded | B23: =COUNTIF(Portfolio!$I$2:$I$139,A23)
A24: Feature of host | B24: =COUNTIF(Portfolio!$I$2:$I$139,A24)
A25: Hosted product | B25: =COUNTIF(Portfolio!$I$2:$I$139,A25)
A26: Hosted web | B26: =COUNTIF(Portfolio!$I$2:$I$139,A26)
A27: Lab harness | B27: =COUNTIF(Portfolio!$I$2:$I$139,A27)
... A37: The hub itself | B37: =COUNTIF(Portfolio!$I$2:$I$139,A37)
A38: Total | B38: =SUM(B16:B37)
A40: By commercial fit
A41: High | B41: =COUNTIF(Portfolio!$M$2:$M$139,A41)
A42: Medium | B42: =COUNTIF(Portfolio!$M$2:$M$139,A42)
A43: Low | B43: =COUNTIF(Portfolio!$M$2:$M$139,A43)
A44: Total | B44: =SUM(B41:B43)
A46: By open-source fit
A47: High | B47: =COUNTIF(Portfolio!$L$2:$L$139,A47)
A48: Medium | B48: =COUNTIF(Portfolio!$L$2:$L$139,A48)
A49: Low | B49: =COUNTIF(Portfolio!$L$2:$L$139,A49)
A50: Total | B50: =SUM(B47:B49)

Sheet Legend
A1: Item | B1: Meaning
A2: Source of truth | B2: scripts/portfolio/portfolio.csv. This workbook and Project Portfolio.md are generated by build_portfolio.py.
A3: Your notes (yellow) | B3: Type in column P; the next build copies them into portfolio.csv. Edits to other columns are overwritten — change those in portfolio.csv.
A4: Open questions | B4: Counted from each spec's §6, the same items handoff_questions.py writes into REPORT.md for the Agents board.
A5: Status | B5: Brownfield (live) = real code. Greenfield = README + spec. Greenfield · host = also absorbs merged features. Merged → feature = lives at <host>/features/<name>/. Parked/Retired = archived on GitHub. Built elsewhere = finished outside E:\GIT_ROOT\Projects.
A6: Fit scores | B6: Judgment calls (High/Medium/Low) from each README's product path, market and privacy constraints; not market research.
